Workbook
Name Slicer_JobType: #N/A
Name Slicer_Region: #N/A
Name Timeline_EstDateTimeStart: #N/A

Sheet Data Tracking - Test file (1)
A1: EstDateTimeStart | B1: Month | C1: Day | D1: JobType | E1: JobStatus | F1: CreatedBy | G1: Technicians | H1: AccountName | I1: Address1 | J1: City | K1: Region | L1: Zip | M1: OrderType | N1: OrderNumber | O1: DateCreated | P1: SubTotal
A2: 45861.583 | B2: July | C2: Wednesday | D2: Air Duct | E2: Complete | F2: Devin James | G2: Dave B, Ty Doe | H2: Durand, Chloé | I2: 2132 Sunset Ct | J2: Cornwall | K2: =_xlfn.XLOOKUP(Data_Tracking___Test_file__1[[#This Row],[City]],'List of Regions'!$A$1:$A$107,'List of Regions'!$B$1:$B$107) -> Kingston | L2: R1N 0P1 | M2: Invoice | N2: 26704 | O2: 45841 | P2: 453
A3: 45861.583 | B3: July | C3: Wednesday | D3: Air Duct | E3: Complete | F3: Chris Hamilton | G3: Chris Smith, Cameron Erroy | H3: Rivard, Emilie | I3: 8672 Maple Ave | J3: Brockville | K3: =_xlfn.XLOOKUP(Data_Tracking___Test_file__1[[#This Row],[City]],'List of Regions'!$A$1:$A$107,'List of Regions'!$B$1:$B$107) -> Kingston | L3: X1B 5A0 | M3: Invoice | N3: 26801 | O3: 45854 | P3: 299
A4: 45861.5 | B4: July | C4: Wednesday | D4: Air Duct | E4: Complete | F4: Devin James | G4: Dave B, Ty Doe | H4: Lemoine, Clara | I4: 6363 Pine St | J4: Cornwall | K4: =_xlfn.XLOOKUP(Data_Tracking___Test_file__1[[#This Row],[City]],'List of Regions'!$A$1:$A$107,'List of Regions'!$B$1:$B$107) -> Kingston | L4: H3E 6C4 | M4: Invoice | N4: 26701 | O4: 45841 | P4: 438
A5: 45861.417 | B5: July | C5: Wednesday | D5: Air Duct | E5: Complete | F5: Lou Mcdonalds | G5: Dave B, Ty Doe | H5: Nguyen, Maxime | I5: 2512 Spruce St | J5: Cornwall | K5: =_xlfn.XLOOKUP(Data_Tracking___Test_file__1[[#This Row],[City]],'List of Regions'!$A$1:$A$107,'List of Regions'!$B$1:$B$107) -> Kingston | L5: V4C 3P6 | M5: Invoice | N5: 26655 | O5: 45833 | P5: 374
A6: 45861.396 | B6: July | C6: Wednesday | D6: Dryer Vent | E6: Complete | F6: Adam Smith | G6: Chris Smith, Cameron Erroy | H6: Fontaine, Julie | I6: 9808 Birch Ln | J6: Harrowsmith | K6: =_xlfn.XLOOKUP(Data_Tracking___Test_file__1[[#This Row],[City]],'List of Regions'!$A$1:$A$107,'List of Regions'!$B$1:$B$107) -> Kingston | L6: P2E 8E9 | M6: Invoice | N6: 26802 | O6: 45854 | P6: 328
A7: 45861.354 | B7: July | C7: Wednesday | D7: Air Duct | E7: Complete | F7: John Doe | G7: Dave B, Ty Doe | H7: Gauthier, Marc | I7: 8577 Birch Ave | J7: Cornwall | K7: =_xlfn.XLOOKUP(Data_Tracking___Test_file__1[[#This Row],[City]],'List of Regions'!$A$1:$A$107,'List of Regions'!$B$1:$B$107) -> Kingston | L7: K3P 5R9 | M7: Invoice | N7: 26728 | O7: 45843 | P7: 404
A8: 45861.333 | B8: July | C8: Wednesday | D8: Joseph Air Duct | E8: Complete | F8: Devin James | G8: Chris Smith, Cameron Erroy | H8: Arsenault, Julien | I8: 9574 Birch Dr | J8: Lake Opinicon | K8: =_xlfn.XLOOKUP(Data_Tracking___Test_file__1[[#This Row],[City]],'List of Regions'!$A$1:$A$107,'List of Regions'!$B$1:$B$107) -> Kingston | L8: V0B 9B0 | M8: Invoice | N8: 26836 | O8: 45859 | P8: 449
A9: 45861.333 | B9: July | C9: Wednesday | D9: Rework | E9: Complete | F9: John Doe | G9: Dave B, Ty Doe | H9: Bélanger, Luc | I9: 8089 Birch Rd | J9: Cornwall | K9: =_xlfn.XLOOKUP(Data_Tracking___Test_file__1[[#This Row],[City]],'List of Regions'!$A$1:$A$107,'List of Regions'!$B$1:$B$107) -> Kingston | L9: X4R 5S2 | M9: Invoice | N9: 26695 | O9: 45840 | P9: 642
A10: 45860.625 | B10: July | C10: Tuesday | D10: Dryer Vent | E10: Complete | F10: Mark Anderson | G10: Dave B, Ty Doe | H10: Tremblay, Pascal | I10: 4006 Willow Ln | J10: Cornwall | K10: =_xlfn.XLOOKUP(Data_Tracking___Test_file__1[[#This Row],[City]],'List of Regions'!$A$1:$A$107,'List of Regions'!$B$1:$B$107) -> Kingston | L10: L2Y 2S9 | M10: Invoice | N10: 26838 | O10: 45859 | P10: 199
A11: 45860.562 | B11: July | C11: Tuesday | D11: Air Duct | E11: Complete | F11: Devin James | G11: Chris Smith, Brad Lisbon | H11: Roy, Hugo | I11: 2954 Pine Blvd | J11: Camden East | K11: =_xlfn.XLOOKUP(Data_Tracking___Test_file__1[[#This Row],[City]],'List of Regions'!$A$1:$A$107,'List of Regions'!$B$1:$B$107) -> Kingston | L11: X7G 4P2 | M11: Invoice | N11: 26707 | O11: 45841 | P11: 453
A12: 45860.5 | B12: July | C12: Tuesday | D12: Air Duct | E12: Complete | F12: Lou Mcdonalds | G12: Chris Smith, Brad Lisbon | H12: Noël, Jonathan | I12: 3727 Spruce Ave | J12: Bath | K12: =_xlfn.XLOOKUP(Data_Tracking___Test_file__1[[#This Row],[City]],'List of Regions'!$A$1:$A$107,'List of Regions'!$B$1:$B$107) -> Kingston | L12: J4R 2M2 | M12: Invoice | N12: 26569 | O12: 45824 | P12: 299
A13: 45860.5 | B13: July | C13: Tuesday | D13: OTTAWA DUCT | E13: Complete | F13: Devin James | G13: Terry Crews, Moris Coldplay | H13: Laroche, Samira | I13: 7271 Spruce Blvd | J13: Ottawa | K13: =_xlfn.XLOOKUP(Data_Tracking___Test_file__1[[#This Row],[City]],'List of Regions'!$A$1:$A$107,'List of Regions'!$B$1:$B$107) -> Ottawa | L13: M1N 3H3 | M13: Invoice | N13: 26735 | O13: 45845 | P13: 533
... A144: 45835.583 | B144: June | C144: Friday | D144: OTTAWA DUCT | E144: Complete | F144: Lou Mcdonalds | G144: Moris Coldplay, Ty Doe | H144: Lambert, Isabelle | I144: 7514 Spruce Way | J144: Ottawa | K144: =_xlfn.XLOOKUP(Data_Tracking___Test_file__1[[#This Row],[City]],'List of Regions'!$A$1:$A$107,'List of Regions'!$B$1:$B$107) -> Ottawa | L144: N1B 7J9 | M144: Invoice | N144: 26467 | O144: 45813 | P144: 398

Sheet List of Regions
A1: City | B1: Region
A2: Ottawa | B2: Ottawa
A3: Manotick | B3: Ottawa
A4: Nepean | B4: Ottawa
A5: Orleans | B5: Ottawa
A6: Dunrobin | B6: Ottawa
A7: Navan | B7: Ottawa
A8: Rockland | B8: Ottawa
A9: Kemptville | B9: Ottawa
A10: Clarence-Rockland | B10: Ottawa
A11: Plantagenet | B11: Ottawa
A12: Casselman | B12: Ottawa
... A107: Oxford Mills | B107: Ottawa

Sheet Pivot table
A3: Total Revenue(SubTotal) | B3: Average revenue per Job
A4: 91067.13 | B4: 636.83308
A6: No.Completed Jobs | B6: Count
A7: Complete | B7: 143
A8: Grand Total | B8: 143
A10: Total Revemnue(SubTotal) | B10: Distinct Count of CreatedBy
A11: 91067.13 | B11: 9
A12: Revenue per Sales Rep | B12: =GETPIVOTDATA("[Measures].[Sum of SubTotal]",$A$10)/GETPIVOTDATA("[Measures].[Distinct Count of CreatedBy]",$A$10) -> 10118.57
D13: Sales Rep according to Performance | E13: Sum of SubTotal
A14: Top 3 Sales Reps | B14: Revenue (SubTotal) | D14: Ava.Leblanc@1Cleanair.Ca | E14: 642
A15: Devin James | B15: 13536.95 | D15: Merry Doris | E15: 1027
A16: Adam Smith | B16: 4198 | D16: John Doe | E16: 1673
A17: Lou Mcdonalds | B17: 2975 | D17: Mark Anderson | E17: 1790.2
A18: Grand Total | B18: 20709.95 | D18: Chris Hamilton | E18: 7475
D19: Lou Mcdonalds | E19: 7671
A20: Region | B20: Revenue (SubTotal) | D20: Adam Smith | E20: 11274
A21: Kingston | B21: 25877 | D21: Devin James | E21: 23637.93
A22: Ottawa | B22: 65190.13 | D22: Hakim.B | E22: 35877
A23: Grand Total | B23: 91067.13 | D23: Grand Total | E23: 91067.13
A25: Job type | B25: Revenue (SubTotal) | D25: Days of the Week | E25: Revenue (SubTotal)
A26: Commercial Work | B26: 32261 | D26: Monday | E26: 22667
A27: Air Duct | B27: 29295 | D27: Tuesday | E27: 18026.93
A28: OTTAWA DUCT | B28: 15809 | D28: Friday | E28: 14905
A29: Duct & Dryer | B29: 3663.2 | D29: Wednesday | E29: 14344.2
A30: Dryer Vent | B30: 3455.96 | D30: Saturday | E30: 12000
A31: Joseph Air Duct | B31: 2055 | D31: Thursday | E31: 9124
A32: Work | B32: 1658.98 | D32: Grand Total | E32: 91067.13
A33: Commercial Estimate | B33: 1349
A34: Rework | B34: 642
A35: Portable Duct | B35: 449
A36: Repair Install Dryer | B36: 299
A37: Portable Dryer | B37: 129.99
A38: Grand Total | B38: 91067.13
A40: Dates | B40: Revenue (SubTotal) | D40: Dates | E40: Count of JobType
A41: Jun | D41: Jun
A42: 27-Jun | B42: 398 | D42: 27-Jun | E42: 1
A43: Jul | D43: Jul
A44: 1-Jul | B44: 4746 | D44: 1-Jul | E44: 8
A45: 2-Jul | B45: 3010 | D45: 2-Jul | E45: 8
A46: 3-Jul | B46: 2446 | D46: 3-Jul | E46: 5
...

Sheet Sheet1
L5: TOTAL REVENUE
